Workbook

Sheet 目录总表
A1: 数据汇总目录清单
A2: 大分类 | B2: 产品专题 | C2: 子产品名称 | D2: 产品介绍 | E2: 点击查看 接口详情 | G2: 个体户模型用途 | H2: 法人模型用途
A3: 企业综合查询 | B3: 工商综合查询 | C3: 工商信息综合查询（大工商） | D3: 查询企业多维度的工商信息，包含： 基本照面信息、股东出资信息、高管信息、法定代表人对外投资信息、法定代表人其他公司任职信息、对外投资、工商变更、清算、行政处罚、失信信息、被执行人信息、经营异常名录、股权出质、动产抵押、股权冻结、分支机构、严重违法信息、简易注销信息、抽查检查信息、年报信息 备注：失信和执行返回最新1000条数据 | E3: =HYPERLINK("#企业综合查询!B"&F3,"跳转") -> 跳转 | F3: =MATCH(C3,企业综合查询!B:B,0) -> 3 | G3: 维度三:经营存续(25%) 工商年限/状态 | H3: 维度一:经营稳定性(30%) 注册年限/经营状态
C4: 企业工商基本信息 | D4: 查询企业照面信息 | E4: =HYPERLINK("#企业综合查询!B"&F4,"跳转") -> 跳转 | F4: =MATCH(C4,企业综合查询!B:B,0) -> 23 | G4: 维度三:经营存续 成立日期/登记状态 | H4: 维度一:经营稳定性 注册年限/状态
C5: 企业分支机构 | D5: 查询企业分支机构 | E5: =HYPERLINK("#企业综合查询!B"&F5,"跳转") -> 跳转 | F5: =MATCH(C5,企业综合查询!B:B,0) -> 60 | H5: 辅助参考
C6: 企业清算信息 | D6: 查询企业清算负责人信息。 | E6: =HYPERLINK("#企业综合查询!B"&F6,"跳转") -> 跳转 | F6: =MATCH(C6,企业综合查询!B:B,0) -> 64 | H6: 辅助参考
C7: 企业工商变更 | D7: 查询企业工商变更记录 | E7: =HYPERLINK("#企业综合查询!B"&F7,"跳转") -> 跳转 | F7: =MATCH(C7,企业综合查询!B:B,0) -> 66 | H7: 辅助参考
C8: 企业动产抵押 | D8: 查询企业动产抵押信息 备注：工商数据公示至2020年，2021年开始在动产融资系统公示。 | E8: =HYPERLINK("#企业综合查询!B"&F8,"跳转") -> 跳转 | F8: =MATCH(C8,企业综合查询!B:B,0) -> 71 | H8: 维度三:履约能力 动产抵押资产验证
C9: 企业抽查检查 | D9: 查询企业抽查检查信息 | E9: =HYPERLINK("#企业综合查询!B"&F9,"跳转") -> 跳转 | F9: =MATCH(C9,企业综合查询!B:B,0) -> 105
C10: 企业双随机抽查 | D10: 查询企业被随机抽查内容及抽查结果等信息。 | E10: =HYPERLINK("#企业综合查询!B"&F10,"跳转") -> 跳转 | F10: =MATCH(C10,企业综合查询!B:B,0) -> 110
C11: 企业股权冻结 | D11: 查询企业股权冻结信息（司法协助） | E11: =HYPERLINK("#企业综合查询!B"&F11,"跳转") -> 跳转 | F11: =MATCH(C11,企业综合查询!B:B,0) -> 121 | H11: 维度四:合规性 股权风险信号
C12: 企业股权出质(工商公示) | D12: 查询非上市企业股权出质信息。 | E12: =HYPERLINK("#企业综合查询!B"&F12,"跳转") -> 跳转 | F12: =MATCH(C12,企业综合查询!B:B,0) -> 136 | H12: 辅助参考
C13: 企业行政许可 | D13: 查询企业行政许可信息 | E13: =HYPERLINK("#企业综合查询!B"&F13,"跳转") -> 跳转 | F13: =MATCH(C13,企业综合查询!B:B,0) -> 159 | H13: 辅助参考
C14: 企业行政处罚 | D14: 查询企业行政处罚信息 | E14: =HYPERLINK("#企业综合查询!B"&F14,"跳转") -> 跳转 | F14: =MATCH(C14,企业综合查询!B:B,0) -> 167 | G14: 维度四:合规稳定性(15%) 处罚记录→扣分 | H14: 维度四:合规性(15%) 处罚次数/金额→扣分
C15: 企业经营异常 | D15: 查询企业历史与当前经营异常信息。 | E15: =HYPERLINK("#企业综合查询!B"&F15,"跳转") -> 跳转 | F15: =MATCH(C15,企业综合查询!B:B,0) -> 181 | G15: 维度四:合规稳定性 异常记录→扣分 | H15: 维度四:合规性 经营异常→扣分
C16: 企业严重违法 | D16: 查询企业严重违法失信信息 | E16: =HYPERLINK("#企业综合查询!B"&F16,"跳转") -> 跳转 | F16: =MATCH(C16,企业综合查询!B:B,0) -> 188 | G16: 一票否决 | H16: 一票否决
C17: 企业简易注销公告 | D17: 返回企业简易注销公告及结果信息。 | E17: =HYPERLINK("#企业综合查询!B"&F17,"跳转") -> 跳转 | F17: =MATCH(C17,企业综合查询!B:B,0) -> 197 | G17: 贷后监控:注销预警 | H17: 贷后监控:注销预警
C18: 企业年报信息 | D18: 查询企业年报信息 | E18: =HYPERLINK("#企业综合查询!B"&F18,"跳转") -> 跳转 | F18: =MATCH(C18,企业综合查询!B:B,0) -> 204 | H18: 维度一:经营稳定性 社保人数(年报)/营收 交叉验证:社保×年报
C19: 企业主要人员查询 | D19: 查询主要人员 | E19: =HYPERLINK("#企业综合查询!B"&F19,"跳转") -> 跳转 | F19: =MATCH(C19,企业综合查询!B:B,0) -> 266 | H19: 辅助参考
C20: 企业股东信息(工商公示)查询 | D20: 查询企业(工商公示)股东信息 | E20: =HYPERLINK("#企业综合查询!B"&F20,"跳转") -> 跳转 | F20: =MATCH(C20,企业综合查询!B:B,0) -> 271 | H20: 辅助参考
C21: 企业股东及出资 | D21: 查询企业股东及出资情况 | E21: =HYPERLINK("#企业综合查询!B"&F21,"跳转") -> 跳转 | F21: =MATCH(C21,企业综合查询!B:B,0) -> 293 | H21: 辅助参考
C22: 企业邮箱/电话/地址/网址信息 | D22: 查询企业邮箱/电话/地址/网址信息 | E22: =HYPERLINK("#企业综合查询!B"&F22,"跳转") -> 跳转 | F22: =MATCH(C22,企业综合查询!B:B,0) -> 314
C23: 企业法定代表人(高管)其他公司任职 | D23: 查询企业法定代表人(高管)其他公司任职情况 | E23: =HYPERLINK("#企业综合查询!B"&F23,"跳转") -> 跳转 | F23: =MATCH(C23,企业综合查询!B:B,0) -> 333 | H23: 辅助参考
C24: 企业法定代表人(高管)对外投资 | D24: 查询企业法定代表人(高管)对外投资情况 | E24: =HYPERLINK("#企业综合查询!B"&F24,"跳转") -> 跳转 | F24: =MATCH(C24,企业综合查询!B:B,0) -> 349 | H24: 维度五:成长性(5%) 对外投资扩张
C25: 企业对外投资查询 | D25: 查询企业对外投资 | E25: =HYPERLINK("#企业综合查询!B"&F25,"跳转") -> 跳转 | F25: =MATCH(C25,企业综合查询!B:B,0) -> 365 | H25: 维度五:成长性 对外投资
C26: 企业Logo | D26: 查询企业logo | E26: =HYPERLINK("#企业综合查询!B"&F26,"跳转") -> 跳转 | F26: =MATCH(C26,企业综合查询!B:B,0) -> 382
C27: 组织机构查询 | D27: 主要适用查询非企业的组织机构信息 | E27: =HYPERLINK("#企业综合查询!B"&F27,"跳转") -> 跳转 | F27: =MATCH(C27,企业综合查询!B:B,0) -> 387
C28: 企业历史股东高管查询 | D28: 查询企业历史法人、股东、高管信息 | E28: =HYPERLINK("#企业综合查询!B"&F28,"跳转") -> 跳转 | F28: =MATCH(C28,企业综合查询!B:B,0) -> 461 | H28: 辅助参考
C29: 企业划型（详版） | D29: 通过企业名称或三码返回企业行业类别、从业人数、资产总额、营业收入、划型规则、企业划型（大型、中型、小型、微型、小微） | E29: =HYPERLINK("#企业综合查询!B"&F29,"跳转") -> 跳转 | F29: =MATCH(C29,企业综合查询!B:B,0) -> 484 | H29: 维度一:经营稳定性 企业划型(大/中/小/微)
B30: 查询工具 | C30: 组织机构模糊查询 | D30: 通过输入组织机构的简称、关键词、英文名、曾用名、统一信用代码、上市代码、商标等获取企业全称。 | E30: =HYPERLINK("#企业综合查询!B"&F30,"跳转") -> 跳转 | F30: =MATCH(C30,企业综合查询!B:B,0) -> 497
C31: 组织机构高级查询 | D31: 企业模糊查询，在组织机构模糊查询的基础上扩展了更多可筛选条件。 | E31: =HYPERLINK("#企业综合查询!B"&F31,"跳转") -> 跳转 | F31: =MATCH(C31,企业综合查询!B:B,0) -> 513
C32: 企业个人名称模糊查询 | D32: 通过输入个人名称关键词查询该人员所在公司及其职位 | E32: =HYPERLINK("#企业综合查询!B"&F32,"跳转") -> 跳转 | F32: =MATCH(C32,企业综合查询!B:B,0) -> 534
B33: 税务专题 | C33: 企业税务综合查询 | D33: 查询企业纳税人类型、纳税评级、欠税信息、非正常户认定信息、重大税收违法信息。 | E33: =HYPERLINK("#企业综合查询!B"&F33,"跳转") -> 跳转 | F33: =MATCH(C33,企业综合查询!B:B,0) -> 540 | H33: 维度一:经营稳定性 纳税信用/欠税/非正常户
C34: 纳税人类型 | D34: 返回查询企业资格类型、识别号等信息。 | E34: =HYPERLINK("#企业综合查询!B"&F34,"跳转") -> 跳转 | F34: =MATCH(C34,企业综合查询!B:B,0) -> 577 | H34: 辅助参考
C35: 纳税信用 | D35: 返回企业纳税评级等信息。 | E35: =HYPERLINK("#企业综合查询!B"&F35,"跳转") -> 跳转 | F35: =MATCH(C35,企业综合查询!B:B,0) -> 581 | H35: 维度一:经营稳定性 纳税评级A/B/C/D→直接评分
B36: 融资专题 | C36: 融资综合查询 | D36: 查询企业创投融资、股权融资、债权融资、银行借款、应收账款融资、租赁融资、银行授信等信息 | E36: =HYPERLINK("#企业综合查询!B"&F36,"跳转") -> 跳转 | F36: =MATCH(C36,企业综合查询!B:B,0) -> 591 | H36: 维度三:履约能力(25%) 7类融资历史
B37: 经营状况专题 | C37: 企业资质证书 | D37: 返回企业各经营领域具有的资质证书信息。 | E37: =HYPERLINK("#企业综合查询!B"&F37,"跳转") -> 跳转 | F37: =MATCH(C37,企业综合查询!B:B,0) -> 850 | H37: 辅助参考
C38: 企业土地信息查询 | D38: 查询企业土地使用、抵押、开发等详细信息。 | E38: =HYPERLINK("#企业综合查询!B"&F38,"跳转") -> 跳转 | F38: =MATCH(C38,企业综合查询!B:B,0) -> 861 | H38: 辅助参考
C39: 企业招投标信息查询 | D39: 查询企业招投标信息 | E39: =HYPERLINK("#企业综合查询!B"&F39,"跳转") -> 跳转 | F39: =MATCH(C39,企业综合查询!B:B,0) -> 915 | H39: 维度三:履约能力 中标率→评分
C40: 招投标详情信息查询 | D40: 通过招投标查询接口获取的关联id获取招投标详情信息 | E40: =HYPERLINK("#企业综合查询!B"&F40,"跳转") -> 跳转 | F40: =MATCH(C40,企业综合查询!B:B,0) -> 939 | H40: 维度三:履约能力 中标金额明细
...

Sheet 企业综合查询
A1: 企业综合查询
A2: 序号 | B2: API名称 | C2: 输入参数 | D2: 具体内容/输出参数
B3: 工商信息综合查询（大工商） | C3: 企业名称、统一信用代码、工商注册号、组织机构代码（4选1） | D3: 企业照面（基本）信息
D4: 股东及出资信息
D5: 主要管理人员信息
D6: 法定代表人对外投资信息
D7: 法定代表人其他公司任职信息
D8: 企业对外投资信息
D9: 企业历史变更信息
D10: 清算信息
D11: 行政处罚历史信息
D12: 失信被执行人信息
D13: 被执行人信息
D14: 经营异常名录记录
D15: 股权出质综合信息
... D22: 年报综合信息
B23: 企业工商基本信息 | C23: 企业名称、统一信用代码、工商注册号、组织机构代码（4选1） | D23: 许可经营项目
D24: 核准日期
D25: 注销日期
D26: 统一信用代码
D27: 地址
D28: 住所所在行政区划
D29: 企业名称
D30: 企业英文名称
D31: 经营状态
D32: 企业类型编码
D33: 企业(机构)类型
D34: 成立日期
D35: 法定代表人/负责人/执行事务合伙人
... D59: 实缴类型
B60: 企业分支机构 | C60: 企业名称、统一信用代码、工商注册号、组织机构代码（4选1） | D60: 分支机构名称
D61: 注册号
D62: 法人
D63: 登记机关
B64: 企业清算信息 | C64: 企业名称、统一信用代码、工商注册号、组织机构代码（4选1） | D64: 清算组负责人
D65: 清算组雇员
B66: 企业工商变更 | C66: 企业名称、统一信用代码、工商注册号、组织机构代码（4选1） | D66: 变更后内容
D67: 变更前内容
D68: 变更日期
D69: 变更事项
...

Sheet 车辆数据
A1: 车辆数据
A2: 数据项 | B2: API名称 | C2: 输入参数 | D2: 具体内容/输出参数
A3: 车辆数据服务I | B3: 车五项 | C3: 车牌号 | D3: vin、发动机号、发动机型号、品牌、初次登记目期、车辆型号
B4: 车辆基本档案 | C4: 车牌/vin | D4: 车辆分类、指导价、使用性质、外廓长、发动机型号、外廓高、发动机号、额定载质量、外廓宽、燃料种类、车架号、品牌、初次登记目期、装备质量、车身颜色、功率、后轮距、总质量、额定牵引总质量、前轮距、轴、车辆类别、车辆种类、车辆型号、轴数、排放标准、排量、额定载客数
B5: 人车二要素 | C5: 姓名、车牌号 | D5: 一致、不一致、查无
B6: 人车三要素 | C6: 姓名、车牌号、号牌种类 | D6: 车牌号(一致/不一致)、号牌种类(一致/不一致)、号牌种类验证状态(一致/不一致)、品牌名称、车身颜色、使用性质、车牌型号、车辆类型、发动机号、发动机型号、车架号、初次登记目期、检验有效期止、机动车所有人验证状态、机动车状态、核定载客数、强制报废期止、燃料种类、排量、出厂日期、最大功率、轴数、轴距、前轮距、后轮距、总重量、整备质 量、核定载质量
B7: 车流向（简版） | C7: 车牌/vin | D7: 初次登记日期、最近一次投保时间、投保省份、投保城市、投保地区
B8: 车流向（详版） | C8: vin | D8: 流出登记日期、最近投保月、使用性质、投保省份、投保城市、投保地区、车牌、品牌、车系、发动机型号、发动机号、排量、出厂日期、车身颜色
B9: 过户 | C9: vin | D9: 过户年月、本次据上次过户月数、本次据上次过户年数、总过户次数过、过户前所在城市，过户后所在城市，过户前车牌，过户后车牌
B10: 出险（详版） | C10: 行驶证 | D10: 当前交强险有效性、交强险出险次数、保险案件拒赔记录，是/否、保险案件未结案记录，是/否、保险案件注销记录，是/否、大额理赔，是/否、是否有过盗抢、是否有过火烧、是否有过水淹、商业险出险次数最大损失金额、出险理赔记录、案件状态、事故原因、事故责任划分、车辆损失金额、是否盗抢、是否火烧、是否水淹、出险时间、出险种类、损伤部位、车辆信息、生产日期、车身颜色、车型类别、车主任数、当前车主类型、当前使用性质、发动机号、排放标准、生产日期、是否有营业记录、车架号、车辆车牌号、号牌种类代码、类别属性、新车购置价、品牌名称、车辆种类、排量、款型名称、核定载客人数、是否有非个人车主情况
B11: 出险（简版） | C11: vin | D11: 车辆款型、燃料种类、类别名称、排量、车身颜色、发动机号、初登目期、新车购置价、订单号、车龄、是否为高风险车辆名单、商业险保单倒计时、交强险保单倒计时、是否投保车损险、是否为连续投保、是否脱保、脱保时间、商业险出险、交强险出险、重大事故标志、损失部位、最高车损险损失比例、车损险综合评分、是否可以投保责任险、是否可以承保延保险、报告下载地址、排放标准、载客人数、小故次数、事故等级、是否为营运车辆、三者出险次数、全损
B12: 维保 | C12: 车架号 | D12: vin 号、行驶里程(km)、维保费用、维保类型、识别订单号、维保项目、维保项目名称、维保材料、维保材料数量、维保材 料名称
A13: 车辆数据服务II | B13: 驾考题库 | C13: 科目，车辆类型，页数 | D13: 基于直连权威数据通道，公安部最新驾照考试题库，分小车、客车、货车、摩托车4类，科目一和科目四2种。可按顺序或者随机获取。
B14: 车辆五项查询 | C14: 车牌号 | D14: 调用车管所全量数据，通过输入车辆的“车牌号”，可直接查询车辆的发动机号、车辆型号、车架号、车辆类型、初登日期等信息。
B15: 车牌查询VIN码 | C15: 车牌号、车辆类型 | D15: 调用车管所全量数据，通过被查询人的“车牌号”和“车辆类型”，可直接查询车辆VIN码，数据精准高效。
B16: 车辆罚单详情查询 | C16: 罚单号 | D16: 调用车管所全量数据，通过授权人提供“罚单号”，直接查询车辆罚单编号、违法状态、罚款金额、违法描述、执法方式等车辆罚单详情。
B17: 汽车品牌大全 | C17: 一级接口无需入参 | D17: 调用车管所全量数据，选择您的汽车品牌，返回对应车辆品牌ID。
B18: 车型大全 | C18: 汽车品牌大全一级ID | D18: 调用车管所全量数据，通过输入“汽车品牌大全一级ID”可对车辆车型大全信息进行全方位查询。
B19: 车型大全详细版 | C19: 车型大全二级ID | D19: 调用车管所全量数据，通过输入“车型大全二级ID”可对车辆车型大全详细版信息进行全方位查询。
B20: 韩国驾驶证信息核验 | C20: 驾驶证基本信息 | D20: 精准核验韩国驾驶证信息，返回结果是否一致，毫秒级响应。
B21: 车辆行驶证四要素核验 | C21: 姓名、身份证号、车牌号、车牌类型 | D21: 调用车管所全量数据，通过被查询人的“姓名”、“身份证号”、“车牌号”、“车牌类型”，可直接核验车辆行驶证四要素信息是否一致，毫秒级检测，返回结果真实有效。
B22: 机动车信息查询 | C22: 车牌号+车牌类型+姓名 | D22: 调用车管所全量数据，通过被查询人的“车牌号”和“车牌类型”（“姓名”选填），查询车辆的中文品牌、车辆识别代号、发动机号、车辆类型、使用性质、初次登记日期、检验有效期止、强制报废期止、机动车状态、发动机型号、燃料种类、排量、功率、轴数、轴距、轴距、后轮距、总质量、整备质量、核定载质量、核定载质量、出厂日期、所有人、车牌号、号牌种类等。
B23: VIN码车辆信息查询_精准版 | C23: 车架号 | D23: 传入车架号，返回车辆信息，包括车辆销售名称、长宽高、指导价、年款、排量、发动机型号等信息
B24: 车辆行驶证信息查询 | C24: 车牌号、车牌类型 | D24: 调用车管所全量数据，通过被查询人的“姓名”、“车牌号”、“证件号”、“车牌颜色 ”，输出指定车辆的行驶证信息：车辆类型、所有人、地址、品牌型号、 使用性质、车辆识别代号、发动机号码、注册日期、发证日期、档案 编号、核定载人数、总质量、整备质量、核定载质量、外廓尺寸、准 牵引总质量
B25: 车辆维保记录查询 | C25: 车架号，车牌号，行驶证图片，发动机号，车辆类型 | D25: 车辆维保数据查询获取订单号后，通过CAR059查具体车辆的出险详情。车辆的维保记录包含：进厂时间，维修类型，车架号，公里数，维修详情，材料详情等。
... B37: 车辆出险记录详版 | C37: 车架号 | D37: 车辆记录查询获取订单号后，通过CAR077查具体车辆的出险记录。
B38: 车辆出险记录详版（异步） | D38: 根据车辆出险产品CAR076返回的订单号，查询具体的车辆出险记录
B39: 车辆VIN码查车辆信息 | C39: VIN | D39: 输入车架号（VIN 码），查询车辆详细信息，包括车牌号，车辆发动机情况，外观情况，车辆类型等。
B40: 驾驶证信息查询 | C40: 姓名、身份证号 | D40: 调用车管所全量数据，通过被查询人的“姓名”和“身份证号”，可直接查询驾驶员性别及其名下的车辆准驾车型、初次领证日期、驾驶证有效期起始日期、驾驶证有效期终止日期、驾驶证状态、驾驶证发证日期、驾驶证种类等。
B41: 车辆投保日期 | C41: 车架号、车牌号、车辆类型 | D41: 调用车管所全量数据，通过输入“车架号”和“车牌号”和“号牌种类”，可直接查询车辆号牌种类，初次投保日期、上次交强险投保年月、最近交强险投保期起止日期等。
B42: 行驶证查询 | C42: 车牌号、车牌类型 | D42: 调用车管所全量数据，通过被查询人的“车牌号”和“车牌类型”（“姓名”选填），查询车辆的中文品牌、车辆识别代号、发动机号、车辆类型、使用性质、初次登记日期、检验有效期止、强制报废期止、机动车状态、发动机型号、燃料种类、排量、功率、轴数、轴距、轴距、后轮距、总质量、整备质量、核定载质量、核定载质量、出厂日期、所有人、车牌号、号牌种类等。
A43: 车辆数据服务III | B43: 乘用车VIN码查询车辆信息 | C43: VIN码 | D43: VIN码、品牌名称、车系名称、车型ID、车型名称、年款、厂商指导价、上市时间、厂商、⻋辆等级、销售状态、车身结构、长*宽*高、整备质量、车门、座位数、排量、档位数、发动机型号、排量(L/T)、发动机描述、最大功率、前制动器类型、后制动器类型、助力类型、轴距、前轮距、后轮距、前轮胎规格、后轮胎规格、备胎规格、驱动方式、变速箱类型、变速箱描述、进气形式、每缸气门数(个)、气缸排列形式、燃油类型、燃油标号、供油方式、排放标准
B44: 商用车VIN码查询车辆信息 | C44: VIN码 | D44: VIN码、品牌名称、车系名称、车型ID、车型名称、年款、厂商指导价、上市时间、厂商、⻋辆等级、销售状态、车身结构、长*宽*高、整备质量、车门、座位数、排量、档位数、发动机型号、排量(L/T)、发动机描述、最大功率、前制动器类型、后制动器类型、助力类型、轴距、前轮距、后轮距、前轮胎规格、后轮胎规格、备胎规格、驱动方式、变速箱类型、变速箱描述、进气形式、每缸气门数(个)、气缸排列形式、燃油类型、燃油标号、供油方式、排放标准
B45: OCR图片识别车架号 | C45: 图片URL地址 | D45: VIN码
B46: 车牌号查询VIN码 | C46: 车牌号码 | D46: VIN码
B47: VIN码查车牌 | C47: VIN码 | D47: 车牌号码
B48: 车辆维保信息 | C48: VIN码、发动机号、车牌号、行驶证图片URL地址 | D48: 报告日期、VIN码、是否火烧、是否泡水、公里数是否正常、最后保养时间、最后维修时间、最后到店时间、最后公里数、重要部件、报告详情、外观部件、结构部件、维保内容、更新时间、品牌、车牌号、发动机号、维保明细类型标签、提示文案、基本情况说明、异常分析说明、初次登记日期、最新上险日期、上险到期日期
B49: 车险查询报告 | C49: VIN码、车牌号、行驶证图片URL地址 | D49: VIN码、品牌、发动机号、车牌号、出险次数、出险总额、出险时间、出险金额、出险详情列表、出险值、出险项目、更换列表（名称/数量）、维修列表（名称/数量）、车型信息、保险信息、损坏部位
B50: 车辆上险查询 | C50: VIN码/车牌号 | D50: 初次登记日期、最新上险日期、上险到期日期
B51: 车辆估值 | C51: VIN码、公里数、上牌时间、地区 | D51: 车商售车价、个人交易、车商收车价
...

Sheet 要素核验
A1: 要素核验
A2: 数据项 | B2: API名称 | C2: 输入参数 | D2: 具体内容/输出参数
A3: 身份核验 | B3: 身份二要素核验 | C3: 企业主的姓名、身份证号 | D3: 提供企业主（企业法人、股东、董事）身份二要素核验
B4: 手机号证件姓名验证 | C4: 企业主的姓名、证件类型、证件号、手机号 | D4: 基于运营商数据，提供企业主手机实名核验
B5: 手机号综合认证 | C5: 企业主的姓名、证件类型、证件号、手机号 | D5: 手机号、姓名与证件号码的三要素核查、手机状态与在网时长
B6: 手机号在网状态以及在网时长 | C6: 企业主的姓名、证件类型、证件号、手机号 | D6: 手机号、姓名与证件号码的手机状态与在网时长
B7: 银行卡三四要素认证 | C7: 姓名、身份证号码、手机号、银行卡号 | D7: 提供个人名下银行卡卡号，开户人姓名，开户人证件号码，开户人预留手机号等要素的实名验证
A8: 企业工商核验 | B8: 企业二要素核验 | C8: 三码、核验类型（1-三码+企业名称核验；2-三码+法定代表人核验）、核验名称（type是1时，填写企业名称；type是2时，填写法定代表人） | D8: 可进行企业三码与企业名称的核验或企业三码与企业法定代表人的核验
B9: 企业三要素核验 | C9: 三码、企业名称、法定代表人姓名 | D9: 可进行企业三码、企业名称和企业法定代表人的核验
B10: 企业四要素核验（企业主核验） | C10: 三码、企业名称、法定代表人姓名、法定代表人身份id | D10: 企业法人核验，核验企业名称、统一社会信用代码、法定代表人姓名及法定代表人身份证是否一致
A11: 个人身份核验 | B11: 出入境证件身份认证 | C11: 证件类型,国籍,出生日期,性别,有效期至,证号,姓名 ,照片（可选） | D11: 基于国家移民管理局授权的官方数据接口，对涉及出入境证件身份核验的场景，提供中国护照，台湾居民来往内地通行证， 港澳居民来往内地通行证，外国居民永久居留身份证的核验服务。有效防范不法分子利用虚假信息或伪假证件违法违规办理各类业务；也可使得拥有在华护照的港澳台同胞在内地的生活便利。
B12: ⾝份二要素核验 | C12: 姓名，身份证号 | D12: 基于公安授权的官方数据接口，通过“姓名”和“身份证号码”信息比对，实现不同应用场景下实时准确的用户身份核验功能。
B13: 人脸识别实人校验 | C13: 姓名，身份证号，照片 | D13: 在用户授权前提下，将姓名、身份证号及采集的人脸照片等信息经过加密算法安全封装，直连公安身份认证体系，使用公安部可信身份权威认证体系的人脸识别AI技术，进行高准确率的身份核验，判断用户是否为「本人」。服务权威可靠，在多种远程业务场景中，如远程身份认证、刷脸门禁、安防、金融KYC等场景使用广泛。平均耗时600毫秒，高效准确，无需等待。
B14: H5认证网关【含电子签约】 | C14: 姓名、证件号、证件类型、回调地址、跳转地址 | D14: 本产品通过集成H5视频采集、视频防伪、活体检测、数据核验、等专业认证技术，生成URL或者二维码，嵌入在企业业务场景中，便于终端用户远程实名、实人认证。认证通过后，可以进行电子合同签署，方便用户展示与通关的功能。基于公安部授权的官方数据接口，覆盖身份证、港澳通行证、台胞证、中国护照等多种身份证件的核验，有效防范不法分子利用虚假信息或伪假证件违法违规办理各类业务；也可使得拥有在华护照的港澳台同胞在内地的生活便利。整个方案采用了H5技术，流程完整，可根据客户需求定制化，企业接入快捷，极大的节省了企业的研发成本。
B15: 全球护照NFC核验 | D15: 用户可在有NFC识别功能的移动端自主完成护照识别、防伪验真，无需人工检查干预。支持全球护照、港澳通行证等其他各类符合ICAO国际旅行的证件，产品以SDK形式提供NFC芯片读取与实证验证，与客户自身APP高度适配，易于集成开发。该服务在KYC、金融、跨国贸易等领域有极其广泛应用场景，极大降低企业人工核验成本，实现便民验证，助力业务打破地域限制远程开展业务。
B16: 证件实名认证 | C16: 姓名、证件号 | D16: 基于直连权威数据通道，通过“姓名”和“证件号”信息比对，实现不同应用场景下实时准确的用户身份核验功能。
B17: H5活体检测 | C17: 姓名、身份证号、视频文件 | D17: 静默视频活体检测产品是一项通过公民身份信息及视频文件录入，对信息进行智能生物识别并与全量官方数据源进行用户身份核验的综合服务产品。适用于银行、互金、电子商务等多个领域全场景的应用，识别率高达99%以上。
B18: 身份证四要素核验 | C18: 姓名、身份证号码、有效期开始日期、有效期截止日期 | D18: 基于直连权威数据通道，对公民身份信息（姓名、身份证号、有效期起始日期、截止日期）进行准确核验，可以实现不同应用场景下的实时核验用户身份。
A19: 银联要素核验 | B19: 银行卡三四要素核验简版 | C19: 姓名、身份证号、银行卡号、手机号（可选） | D19: 直连银行体系全量实时接口，数据库覆盖全国3000多家银行，动态及时更新，通过授权银行卡四要素（姓名、身份证号、卡号、手机号），极速验证银行卡信息是否一致。
B20: 企业银行账户核验 | C20: 企业代码类型、企业代码、企业名称、企业法人、企业账户账号、企业账户开户行 | D20: 直连银行体系全量实时接口，数据库覆盖全国3000多家银行，动态及时更新，通过输入企业代码类型、企业代码、企业名称、企业法人等信息，极速核验企业银行账户。毫秒级速度体验，每秒万次认证服务能力，最大程度确保验证信息的准确率。
B21: 银行卡二要素核验简版 | C21: 姓名，银行卡号 | D21: 直连银行体系全量实时接口，数据库覆盖全国3000多家银行，动态及时更新，通过授权银行卡二要素（姓名”和“银行卡号”），极速验证银行卡信息是否一致。
B22: 银行卡账户类型查询 | C22: 银行卡号 | D22: 直连银行体系全量实时接口，数据库覆盖全国大中小型多家银行，动态及时更新，通过银行卡号返回该银行卡类型。毫秒级速度体验，每秒万次认证服务能力，最大程度确保验证信息的准确率。
B23: 银行卡涉赌涉诈查询 | C23: 卡号 | D23: 输入银行卡号，查询银行卡的风险标签、账户类型、归属地等信息
B24: 银行卡联行号查询 | C24: 卡号、银行名称，银行开户行、身份、城市 | D24: 银行联行号查询，可根据关键字，银行名称、银行卡号，省，市等信息查询，返回联行号，支行名称，电话、地址，银行Logo等信息。
B25: 银行卡黑名单核验 | C25: 身份证号、银行卡号、电话号码 | D25: 依托专属通道全量数据,根据授权人提供的身份证号、银行卡号、电话号码，查询黑名单信息。毫秒级速度体验，每秒万次认证服务能力，最大程度确保验证信息的准确率。
B26: 银行卡认证详情版 | C26: 姓名、身份证号、银行卡号 | D26: 直连银行体系权威全量实时接口，毫秒级响应，权威数据库动态更新，覆盖全国3000多家银行。 基于银行卡授权三要素（姓名、身份证号、卡号），极速鉴权并返回验证详情，同时查询银行名称、银行卡类型、等级等银行卡信息。
B27: 银行卡归属地查询 | C27: 卡号 | D27: 直连银行体系全量实时接口，数据库覆盖全国3000多家银行，动态及时更新，通过银行卡号，极速核验用户银行卡归属地信息。毫秒级速度体验，每秒万次认证服务能力，最大程度确保验证信息的准确率。
B28: 银行卡特征及评分 | C28: 用户姓名、身份证号、银行卡号、手机号 | D28: 直连银行体系全量实时接口，数据库覆盖全国3000多家银行，动态及时更新，通过授权银行卡五要素（“姓名”、“身份证号”、“卡号”、“手机号”），极速查询该用户银行卡交易详情，包括交易金额、消费行业等，用于评估该被查询人消费水平。毫秒级速度体验，每秒万次认证服务能力，最大程度确保验证信息的准确率。
A29: 运营商要素核验 | B29: 短信验证码 | C29: 手机号 | D29: 短信验证直连运营商全量实时接口，根据手机号，向对应用户手机发送包含验证码的短信。短信模板支持自定义，录入使用需审核。网关提交，最高流速达到5000条/秒，验证码5秒送达且到达率高达99%。
B30: 手机号归属地 | C30: 姓名、手机号 | D30: 根据手机号码实时判断省份和城市,精准高效地查询到号码归属地。
B31: 手机近三个月话费查询 | C31: 手机号 | D31: 调用三大运营商核验接口，基于用户授权”手机号“，极速查询请求的手机号近三个月话费均值，检测结果实时返回，毫秒级响应速度。
B32: 手机三要素简版核验 | C32: 姓名、身份证号、手机号 | D32: 调用三大运营商核验接口，基于用户三要素授权（“姓名”、“身份证号”与“手机号”），极速验证身份证信息是否一致并获取手机号归属地（省、市）、手机号所属运营商（中文及英文标识）信息。检测结果实时返回，毫秒级响应速度，直从源头杜绝用户欺诈。
B33: 手机号在网时长查询 | C33: 手机号,支持md5 | D33: 直接调用三大运营商直连接口，基于用户"手机号”，精准查询手机号在网时长及运营商信息，实时反馈准确的查询结果，毫秒级返回速度，精准高效。
B34: 手机近3个月的停机次数 | C34: 手机号码,运营商类型（选填） | D34: 调用三大运营商核验接口，基于用户授权手机号，极速验证手机号所属运营商（中文及英文标识），获取该号码近六个月的停机次数。检测结果实时返回，毫秒级响应速度。
B35: 运营商三要素核查详版 | C35: 姓名，手机号，身份证号 | D35: 调用三大运营商核验接口，基于用户三要素授权（“姓名”、“身份证号”与“手机号”），极速验证身份证信息是否一致。检测结果实时返回，毫秒级响应速度，直从源头杜绝用户欺诈。
B36: 运营商三要素核查简版MD5 | C36: 姓名，手机号，身份证号 全部(MD5【32位小写】) | D36: 调用三大运营商核验接口，基于用户三要素授权（“姓名”、“身份证号”与“手机号”），极速验证身份证信息是否一致。检测结果实时返回，毫秒级响应速度，直从源头杜绝用户欺诈。
B37: 手机二要素MD5 | C37: 姓名（md5）、手机号 （md5） | D37: 调用三大运营商核验接口，基于用户二要素授权（“姓名”和“手机号"），极速验证身份证信息是否一致并获取手机号归属地（省、市）手机号所属运营商（中文及英文标识）信息。检测结果实时返回，毫秒级响应速度，直从源头杜绝用户欺诈。
B38: 手机二要素核验 | C38: 姓名、手机号码,运营商类型(选填) | D38: 调用三大运营商核验接口，基于用户二要素授权（“姓名”和“手机号"），极速验证信息是否一致、并返回手机号所属运营商（中文及英文标识）信息。检测结果实时返回，毫秒级响应速度，直从源头杜绝用户欺诈。
B39: 近三个月流量均值 | C39: 手机号，运营商（选填：1：移动 3：电信） 支持md5 | D39: 调用运营商流量接口，基于手机号所属运营商（中文及英文标识）信息，查询近三个月平均流量信息，毫秒级响应速度。
B40: 手机号三个月通话时长查询 | C40: 手机号，运营商（选填） | D40: 调用三大运营商核验接口，基于用户手机号，手机号所属运营商。查询近三个月通话时长信息，检测结果实时返回，毫秒级响应速度。
...

Sheet 个人信用
A1: 个人信用
A2: 数据项 | B2: API名称 | C2: 输入参数 | D2: 具体内容/输出参数
A3: 个人风险查询 | B3: 地址核验 | C3: 手机号、地址、回溯日期 | D3: 对运营商（手机号、地址、回溯日期）进行准确核验，可以实现不同应用场景下的实时核验地址一致性。
B4: 检测羊毛党 | C4: IP地址，手机号 | D4: 通过大数据分析和数据模型来确定手机号码是否为"羊毛党"的，当用户传送手机号给我们时，我们会在各种数据库筛选，发现与该手机号有关的各种行为，来综合判断手机号码是真实"用户"还是"羊毛党"。调用数十亿海量数据分析与黑名单库动态实时更新，多维度、多情景精准防护，杜绝垃圾账号注册。
B5: 逾选指数 | C5: 手机号 | D5: 用户授权后，根据提供的手机号，可对其信贷逾期详细情况进行核验，全面助力提高金融行业反欺诈和风控水平、降低金融机构的经营风险和资金成本。
B6: 付选指数 | C6: 姓名、手机号、身份证号 | D6: 用户授权后，根据提供的姓名、手机号、身份证号，可对其在线支付消费详细情况进行核验，全面助力提高金融行业反欺诈和风控水平、降低金融机构的经营风险和资金成本。
B7: 贷选指数 | C7: 姓名、手机号、身份证号 | D7: 用户授权后，根据提供的姓名、手机号、身份证号，可对其信贷详细情况进行核验，全面助力提高金融行业反欺诈和风控水平、降低金融机构的经营风险和资金成本。
B8: 信选指数 | C8: 姓名，身份证号，手机号 | D8: 基于全国可信数据源官方授权，通过输入被查询人的”姓名，身份证号，手机号“，可对其信贷详细情况进行核验，全面助力提高金融行业反欺诈和风控水平、降低金融机构的经营风险和资金成本。
B9: 借选指数 | C9: 姓名，身份证号，手机号，授权码 | D9: 基于全国可信数据源官方授权，通过输入被查询人的”姓名，身份证号，手机号“，可对其多方借贷详细情况进行核验，全面助力提高金融行业反欺诈和风控水平、降低金融机构的经营风险和资金成本。
B10: 常住地核验 | C10: 姓名；身份证号；手机号 | D10: 根据用户行为轨迹评估其常住地。
B11: 身份证实名校验 | C11: 姓名；身份证号 | D11: 验证姓名和身份证号是否一致
B12: 身份证三要素 | C12: 姓名；身份证号；手机号 | D12: 验证姓名、手机号、身份证号是否一致
B13: 不良行为 | C13: 姓名；身份证号 | D13: 传入姓名、身份证号核查不良行为信息
B14: 司法行为 | C14: 姓名；身份证号 | D14: 个人涉诉查询
A15: 个人信用评分 | B15: 还款能力测评 | C15: 姓名，身份证号，手机号 | D15: 依托机器学习通过评分卡建模技术，对用户行为进行评分，多维度综合分析用户的收入水平。只需输入候选人姓名、手机号及身份证号，即可对其还款能力进行全方位评估。
B16: 社保综合评分 | C16: 姓名、身份证号、手机号 | D16: 依托传统评分卡技术与业界领先的数据安全及机器学习建模技术等有机融合，对用户行为进行评分。只需输入候选人姓名、手机号及身份证号，即可对其还款能力、还款稳定性以及信用历史长度进行全方位评估。
A17: 借贷意向 | B17: 借贷意向验证简版 | C17: 姓名、身份证号、手机号 | D17: 评估个体近7/15天、1/3/6/12个月的多次申请信贷情况。
B18: 借贷意向验证细分版 | C18: 姓名、身份证号、手机号 | D18: 近2/3/6/12/18/24个月，用户在银行/非银等机构申请的次数/机构数
A19: 经济评分预测 | B19: 经济能力预测评分A | C19: name:姓名（支持明文或32位md5） idCard:身份证号码（支持明文或32位md5） | D19: 预测个人收入水平评分，区间段含义如下： N、缺失值 10、[0,2000) 20、[2000,4000) 30、[4000,6000) 40、[6000,8000) 50、[8000,10000) 60、[10000,15000) 70、[15000,20000) 80、[20000,30000) 90、[30000,40000) 100、[40000,50000) 110、[50000,+)
B20: 经济能力预测评分B | C20: name、idCard、mobile三要素（支持md5、sha256、sm3加密） | D20: 根据收入和支出等互联网标签、资产属性等多维数据，覆盖银行、互联网、消费金融等场景客户群体，产品输出： （1）消费能力指数，0-10w范围1k一档，区间左闭右开，10w+单独一档 例如：（0, 10）代表消费在0-1000 （2）消费稳定性指数 例如：（0, 3) 代表最近 2 年消费的月份数为0-3个月
B21: 经济能力预测评分S | C21: name:姓名（支持明文或32位md5） idCard:身份证号码（支持明文或32位md5） | D21: 预测个人收入水平评分，区间段含义如下： N、缺失值 10、[0,2000) 20、[2000,4000) 30、[4000,6000) 40、[6000,8000) 50、[8000,10000) 60、[10000,15000) 70、[15000,20000) 80、[20000,30000) 90、[30000,40000) 100、[40000,50000) 110、[50000,+)
B22: 信用预测评分A | C22: name、idCard、mobile三要素（支持md5、sha256、sm3加密） | D22: 评分区间200-800之间，分数越低， 资信水平越差，信用风险越高；分数越高，资信 水平越好，信用风险越低，精准预测被查询人的 资信水平，识别被查询人贷款信用风险。
B23: 个税 | C23: 姓名、身份证号、手机号 | D23: 评分 [300,320)、(0,1000] [320,340)、(1000,2000] [340,360)、(2000,3000] [360,380)、(3000,4000] [380,400)、(4000,5000] [400,420)、(5000,6000] [420,440)、(6000,7000] [440,460)、(7000,8000] [460,480)、(8000,9000] [480,490)、(9000,10000] [490,500)、(10000,11000] [500,510)、(11000,12000] [510,520)、(12000,13000] [520,530)、(13000,14000] [530,540)、(14000,15000] [540,550)、(15000,16000] [550,560)、(16000,17000] [560,570)、(17000,18000] [570,580)、(18000,19000] [580,590)、(19000,20000] [590,600)、(20000,22000] [600,610)、(22000,24000] [610,620)、(24000,26000] [620,630)、(26000,28000] [630,640)、(28000,30000] [640,650)、(30000,32000] [650,660)、(32000,34000] [660,670)、(34000,36000] [670,680)、(36000,38000] [680,690)、(38000,40000] [690,700)、(40000,42000] [700,710)、(42000,44000] [710,720)、(44000,46000] [720,730)、(46000,48000] [730,740)、(48000,50000] [740,750]、(50000,+]
B24: 社保 | C24: 姓名、身份证号、手机号 | D24: 预测模型评分 评分 描述 0 ⽆法预测 10～19 预测⾦融能⼒：(0，1500] 20～29 预测⾦融能⼒：(1500，3000] 30～39 预测⾦融能⼒：(3000，4500] 40～49 预测⾦融能⼒：(4500，6000] 50～59 预测⾦融能⼒：(6000，8000] 60～69 预测⾦融能⼒：(8000，10000] 70～79 预测⾦融能⼒：(10000，13000] 80～89 预测⾦融能⼒：(13000，16000] 90～99 预测⾦融能⼒：(16000，20000] 100 预测⾦融能⼒：20000+
D25: 稳定性模型评分 评分 描述 0 ⽆法预测 20～39 近期稳定指数预测：(0，6] 40～59 近期稳定指数预测：(6，12] 60～79 近期稳定指数预测：(12，18] 80～99 近期稳定指数预测：(18，24) 100 近期稳定指数预测：24
D26: 历史属性评分 评分 描述 0 ⽆法预测 10～19 历史属性指数预测：(0，6] 20～29 历史属性指数预测：(6，12] 30～39 历史属性指数预测：(12，24] 40～49 历史属性指数预测：(24，36] 50～59 历史属性指数预测：(36，48] 60～69 历史属性指数预测：(48，60] 70～79 历史属性指数预测：(60，84] 80～89 历史属性指数预测：(84，120] 90～99 历史属性指数预测：(120，180] 100 历史属性指数预测：180+

Sheet HR职业评测
A1: HR职业测评
A2: 数据项 | B2: API名称 | C2: 输入参数 | D2: 具体内容/输出参数
B3: 学位信息核验 | C3: 姓名、身份证号码、学位证书编号 | D3: 基于合规的官方数据接口，通过“姓名”和“身份证号码”、"学位证书编号"信息比对，实现不同应用场景下实时准确的学位信息核验。
B4: 公积金基本信息查询 | C4: 姓名、身份证号、手机号 | D4: 基于全国可信数据源官方授权，通过输入被查询人的”姓名、身份证号“和“手机号”，实时返回被查询人的公积金基本汇缴信息等。
B5: 可信度查询V3 | C5: 身份证号 | D5: 基于全国可信数据源官方授权，协助企业人力资源部门核验应聘者的潜在风险。为企业从源头杜绝用人带来的潜在资金与品牌损失和风险。
B6: 可信度查询V8 | C6: 身份证号MD5 | D6: 基于全国可信数据源官方授权，协助企业人力资源部门核验应聘者的潜在风险。为企业从源头杜绝用人带来的潜在资金与品牌损失和风险。
B7: 还款能力等级 | C7: 姓名，身份证号，手机号 | D7: 依托机器学习通过评分卡建模技术，对用户行为进行评分，多维度综合分析用户的收入水平。只需输入候选人姓名、手机号及身份证号，即可对其还款能力进行全方位评估。
B8: 社会负面安全核验 | C8: 姓名、身份证号 | D8: 基于全国可信数据源官方授权，协助企业人力资源部门核验应聘者的潜在风险。为企业从源头杜绝用人带来的潜在资金与品牌损失和风险。
B9: 学历信息核验 | C9: 姓名、身份证号码、毕业证书编号 | D9: 基于合规授权的官方数据接口，通过“姓名”和“身份证号码”、"毕业证书编号"信息比对，实现不同应用场景下实时准确的学历信息核验。
B10: 学历查询（旗舰版） | C10: 姓名，身份证号 | D10: 院校名称 专业名称 学历层次 学习形式 毕业日期
B11: 学历查询（钻石版） | C11: 姓名，身份证号 | D11: 专业名称 学历 学校类型 入学时间 毕业日期 学习形式
B12: 学籍信息查询 | C12: 姓名、身份证号 | D12: 通过评分来判断该自然人在籍、不在籍、无法判断
B13: 个人工商 | C13: 姓名和身份证号 | D13: 查询人对应企业名 查询人持股信息 股东类型 出资时间 占比 出资金额 股东名 查询人与这家企业的关联:sh股东;lp法人;t高管查询人所在公司基本信息 企业状态 成立日期 注册资本 行业 主要人员 主要人员名称 人员类型 1-公司;2-个人 职位 法人类型，1-人;2-公司 注册资本市种:人民币、美元、欧元等 法人姓名 注册号 统一社会信用代码 公司名称 企业类型 省份简称
B14: 个税 | C14: 上下文ID（需取得用户授权后获取ID）,所属年份止。格式：yyyy，默认当年,所属年度起。格式：yyyy，默认当年 （需用户强授权：APP或短信授权） | D14: 所属期起,所属期止,所得项目（工资新进所得、劳务报酬所得、稿酬所得、特许权使用费所得、经营所得、财产租赁所得、财产转让所得、利息股息红利所得、偶然所得）,扣缴义务人,本期收入,已申报税额

Sheet 司法涉诉
A1: 司法涉诉
A2: 数据项 | B2: API名称 | C2: 输入参数 | D2: 具体内容/输出参数
A3: 个人或企业司法 | B3: 司法综合资讯 | C3: 主体类型（0：个人 1：企业） 企业名称、组织机构代码 主体名称、证件号码、证件类型 查询涉诉类型（zonghe--综合涉诉 shixin--失信被执行 xiangao--限高被执行） | D3: 司法涉诉信息
D4: 案件树及明细
D5: 刑事案件统计数据
D6: 刑事案件案件详情
D7: 民事案件统计数据
D8: 民事案件案件详情
D9: 行政案件统计数据
D10: 行政案件案件详情
D11: 执行案件统计数据
D12: 执行案件案件详情
D13: 强制清算与破产案件统计数据
D14: 强制清算与破产案件案件详情
D15: 统计数据
... D74: 发布时间
A75: 企业司法涉诉 | B75: 企业司法检索 | C75: 企业名称、统一信用代码、工商注册号、组织机构代码（4选1） 数据类型【zhixing(执行公告) shixin(失信公告) cpws(裁判文书) kaiting(开庭公告) fayuan(法院公告) ajlc(案件流程) bgt(曝光台) sifacdk(司法查冻扣) paimai(拍卖公告)】 | D75: 数据类型
D76: 详情ID，用于后续详情查询
D77: 内容概要
D78: 内容标题
D79: 数据时间
D80: 历史数据标志位（0表示历史）
B81: 企业司法详情 | C81: 详情id，数据类型【zhixing(执行公告) shixin(失信公告) cpws(裁判文书) kaiting(开庭公告) fayuan(法院公告) ajlc(案件流程) bgt(曝光台) sifacdk(司法查冻扣) paimai(拍卖公告)】 | D81: 执行数据列表
D82: 失信数据列表
D83: 裁判文书列表
D84: 开庭公告列表
D85: 法院公告列表
D86: 案件流程列表
D87: 曝光台列表（限制高消费）
D88: 司法查冻扣列表
D89: 拍卖公告列表
B90: 企业开庭公告 | C90: 企业名称、统一信用代码、工商注册号、组织机构代码（4选1） | D90: 开庭公告id
D91: 开庭时间
D92: 原告
D93: 开庭法院
D94: 案由
D95: 案号
D96: 被告
D97: 角色
B98: 企业终本案件 | C98: 企业名称、统一信用代码、工商注册号、组织机构代码（4选1） | D98: 当页数据
...

Sheet 企业财税
A1: 企业财税
A2: 数据项 | B2: API名称 | C2: 输入参数 | D2: 具体内容/输出参数
A3: 发票数据 | B3: 发票基础信息 | C3: 税号、开票开始时间、开票结束时间、进销项标识 、当前页 、每页的数量、销方名称、查询原因、信息主体授权码、信息主体授权日期 | D3: 进销项 销（进）方名称 销方纳税人识别号 销方地址电话 销方开户行及账号 购方名称 购方纳税人识别号 购方地址电话 购方开户行及账号 金额合计（不含税） 税额合计 价税合计(小写) 开票人 发票代码 发票号码 开票日期 校验码 发票种类 发动机号码 车辆识别代号/车架号码 限乘人数 车辆类型 进口证明书号 吨位 产地 商检单号 厂牌型号 合格证号 发票状态 发票明细项
A4: 财务报表 | B4: 财务基础信息 | C4: 税号、订单号、查询原因、信息主体授权码、信息主体授权日期 | D4: 资产负债表（年报）
D5: 资产负债表（季报）
D6: 利润表（年报）
D7: 利润表（季报）
D8: 现金流量表
A9: 发票数据 | B9: API发票基础信息 | C9: 企业名称、统一信用代码 | D9: 企业基本信息、主要人员信息、股东信息、分支机构、企业变更信息、经营异常信息、企业经营信息、上下游交易分析 | H9: 0775 3116883
A10: 财税综合 | B10: API发票+纳税基础信息 | C10: 企业名称、统一信用代码 | D10: 企业基本信息、开票按月汇总信息、上游按月汇总信息、下游按月汇总信息、地区销售按月汇总信息、商品销售按月汇总信息、纳税申报信息、缴款信息、利润表信息、资产负债表信息、欠税信息、违法违章信息
A11: 企业纳税 | B11: 纳税基础信息 | C11: 税号、查询原因、信息主体授权码、信息主体授权日期 | D11: 公司登记信息
D12: 纳税信用等级
D13: 变更税务登记信息
D14: 股东信息
D15: 增值税申报表明细（一般纳税人）
D16: 增值税申报表明细（小规模纳税人）
D17: 企业所得税纳税申报表-月（季）度
D18: 企业所得税申报表-年度
D19: 社会保险费申报表
D20: 完税证明信息
D21: 税务修改记录
D22: 欠税信息
D23: 稽查检查文书信息
D24: 税收违法违章信息
B25: 企业核心财务指标 | C25: 企业名称、统一信用代码、工商注册号、组织机构代码（4选1） | D25: 企业名称 统一社会信用代码 工商注册码 组织机构代码 行业代码 行业名称 企业所属二级行业 企业所属二级行业 年报年度 资产总额 负债总额 营业总收⼊ 主营业务收⼊ 利润总额 净利润 纳税总额 所有者权益合计 企业社保⼈数 企业从业⼈数 净利润率 资产周转率 总资产负债率 资产净利率 净资产收益率 资产总额增⻓率 负债总额增⻓率 营业总收⼊增⻓率 主营业务收⼊增⻓率 利润总额增⻓率 净利润增⻓率 纳税总额增⻓率 所有者权益合计增⻓率 净利润率二级行业均值 资产周转率二级行业均值 总资产负债率二级行业均值 资产净利率二级行业均值 净资产收益率二级行业均值 资产总额增⻓率二级行业均值 负债总额增⻓率二级行业均值 营业总收⼊增⻓率二级行业均值 主营业务收⼊增⻓率二级行业均值 利润总额增⻓率二级行业均值 净利润增⻓率二级行业均值 纳税总额增⻓率二级行业均值 所有者权益合计增⻓率二级行业均值
B26: 财务分析报告查询 | C26: 分析报告ID、服务类型、查询原因、业务描述、信息主体授权码、信息主体授权时间 | D26: 分析报告内容 资产结构分析 现金流量分析 公司名称 综合报告 经营协调性分析 成本费用分析 发展能力分析 负债及权益结构分析 营运能力分析 盈利能力分析 实现利润分析 偿债能力分析 财务报告年份 分析报告状态 返回的分析报告类型，文件url/内容 分析报告url
B27: 企业财务状况综合查询 | C27: 企业名称、统一信用代码、工商注册号、组织机构代码（4选1） | D27: 企业现金流量表 数据日期 408001000：合并报表 ; 408006000：母公司报表 销售商品、提供劳务收到的现金 收到的税费返还 客户存款和同业存放款项净增加额 向中央银行借款净增加额 向其他金融机构拆入资金净增加额 收到原保险合同保费取得的现金 保户储金净增加额 收到再保业务现金净额 处置交易性金融资产净增加额 收取利息和手续费净增加额 处置可供出售金融资产净增加额 拆入资金净增加额 回购业务资金净增加额 收到其他与经营活动有关的现金 经营活动现金流入小计 购买商品、接受劳务支付的现金 支付给职工以及为职工支付的现金 支付的各项税费 客户贷款及垫款净增加额 存放央行和同业款项净增加额 支付原保险合同赔付款项的现金 支付手续费的现金 支付保单红利的现金 支付其他与经营活动有关的现金 经营活动现金流出小计 经营活动产生的现金流量净额 收回投资收到的现金 取得投资收益收到的现金 处置固定资产、无形资产和其他长期资产收回的现金净额 处置子公司及其他营业单位收到的现金净额 收到其他与投资活动有关的现金 投资活动现金流入小计 购建固定资产、无形资产和其他长期资产支付的现金 投资支付的现金 取得子公司及其他营业单位支付的现金净额 支付其他与投资活动有关的现金 质押贷款净增加额 投资活动现金流出小计 投资活动产生的现金流量净额 吸收投资收到的现金 其中:子公司吸收少数股东投资收到的现金 取得借款收到的现金 发行债券收到的现金 收到其他与筹资活动有关的现金 筹资活动现金流入小计 偿还债务支付的现金 分配股利、利润或偿付利息支付的现金 其中:子公司支付给少数股东的股利、利润 支付其他与筹资活动有关的现金 筹资活动现金流出小计 筹资活动产生的现金流量净额 汇率变动对现金的影响 现金及现金等价物净增加额 期初现金及现金等价物余额 期末现金及现金等价物余额 企业利润表 数据日期 408001000：合并报表 ; 408006000：母公司报表 营业总收入 营业收入 利息收入 利息净收入 已赚保费 手续费及佣金收入 手续费及佣金净收入 其他经营净收益 加:其他业务净收益 保费业务收入 减:分出保费 提取未到期责任准备金 其中:分保费收入 代理买卖证券业务净收入 证券承销业务净收入 受托客户资产管理业务净收入 其他业务收入 加:公允价值变动净收益 加:投资净收益 其中:对联营企业和合营企业的投资收益 加:汇兑净收益 营业总成本 减:营业成本 减:利息支出 减:手续费及佣金支出 减:营业税金及附加 减:销售费用 减:管理费用 减:财务费用 减:资产减值损失 退保金 赔付总支出 提取保险责任准备金 保户红利支出 分保费用 营业支出 减:摊回赔付支出 减:摊回保险责任准备金 减:摊回分保费用 其他业务成本 营业利润 加:营业外收入 减:营业外支出 其中:减:非流动资产处置净损失 利润总额 所得税 未确认投资损失 净利润(含少数股东损益) 净利润(不含少数股东损益) 少数股东损益 其他综合收益 综合收益总额 综合收益总额(母公司) 综合收益总额(少数股东) 其他收益 企业资产负债表 数据日期 408001000：合并报表 ; 408006000：母公司报表 货币资金 交易性金融资产 应收票据 应收账款 其他应收款 预付款项 应收股利 应收利息 存货 消耗性生物资产 待摊费用 一年内到期的非流动资产 结算备付金 拆出资金 应收保费 应收分保账款 应收分保合同准备金 买入返售金融资产 其他流动资产 流动资产合计 可供出售金融资产 持有至到期投资 长期股权投资 投资性房地产 定期存款 其他资产 长期应收款 固定资产 在建工程 工程物资 固定资产清理 生产性生物资产 油气资产 无形资产 开发支出 商誉 长期待摊费用 递延所得税资产 发放贷款及垫款 其他非流动资产 非流动资产合计 现金及存放中央银行款项 存放同业和其它金融机构款项 贵金属 衍生金融资产 代理业务资产 应收代位追偿款 应收分保未到期责任准备金 应收分保未决赔款准备金 应收分保寿险责任准备金 应收分保长期健康险责任准备金 存出保证金 保户质押贷款 存出资本保证金 独立账户资产 客户资金存款 客户备付金 其中:交易席位费 应收款项类投资 资产总计 短期借款 向中央银行借款 吸收存款及同业存放 拆入资金 交易性金融负债 应付票据 应付账款 预收款项 卖出回购金融资产款 应付手续费及佣金 应付职工薪酬 应交税费 应付利息 应付股利 其他应付款 预提费用 递延收益 应付短期债券 应付分保账款 保险合同准备金 代理买卖证券款 代理承销证券款 一年内到期的非流动负债 其他流动负债 流动负债合计 长期借款 应付债券 长期应付款 专项应付款 预计负债 递延所得税负债 递延收益-非流动负债 其他非流动负债 非流动负债合计 同业和其它金融机构存放款项 衍生金融负债 吸收存款 代理业务负债 其他负债 预收保费 存入保证金 保户储金及投资款 未到期责任准备金 未决赔款准备金 寿险责任准备金 长期健康险责任准备金 独立账户负债 其中:质押借款 应付赔付款 应付保单红利 负债合计 股本 资本公积金 专项储备 盈余公积金 未分配利润 减:库存股 一般风险准备 外币报表折算差额 未确认的投资损失 少数股东权益 股东权益合计(不含少数股东权益) 股东权益合计(含少数股东权益) 负债及股东权益总计 企业主要指标(财务报表) 数据日期 每股收益-基本 (元) 每股收益-稀释 (元) 每股收益-扣除/基本 (元) 每股净资产 (元) 每股经营活动产生的现金流量净额 每股资本公积 (元) 每股未分配利润 (元) 每股收益-基本 (元)-中位数 每股收益-稀释 (元)-中位数 每股收益-扣除/基本 (元)-中位数 每股净资产 (元)-中位数 每股经营活动产生的现金流量净额-中位数 每股资本公积 (元)-中位数 每股未分配利润 (元)-中位数 营业总收入同比增长率 营业收入同比增长率 同比增长率-利润总额 营业总收入同比增长率中位数 营业收入同比增长率中位数 同比增长率-利润总额中位数 净资产收益率(摊薄) 净资产收益率(加权) 净资产收益率(年化) 总资产报酬率 总资产报酬率(年化) 销售净利率 销售毛利率 营业利润/营业总收入 净资产收益率(摊薄)-中位数 净资产收益率(加权)-中位数 净资产收益率(年化)-中位数 总资产报酬率-中位数 总资产报酬率(年化)-中位数 销售净利率-中位数 销售毛利率-中位数 营业利润/营业总收入-中位数 销售收到现金流/营业收入 经营现金流/营业收入 销售收到现金流/营业收入-中位数 经营现金流/营业收入-中位数 应收账款周转天数 存货周转天数 总资产周转率 应收账款周转天数-中位数 存货周转天数-中位数 总资产周转率-中位数 流动比率 速动比率 利息保障倍数 流动比率-中位数 速动比率-中位数 利息保障倍数-中位数 流动资产/资产合计 非流动资产/资产合计 流动负债/负债合计 非流动负债/负债合计 资产负债率 流动资产/资产合计-中位数 非流动资产/资产合计-中位数 流动负债/负债合计-中位数 非流动负债/负债合计-中位数 资产负债率-中位数
B28: 企业现金流表查询 | C28: 企业名称、统一信用代码、工商注册号、组织机构代码（4选1） | D28: 数据日期 408001000：合并报表 ; 408006000：母公司报表 销售商品、提供劳务收到的现金 收到的税费返还 客户存款和同业存放款项净增加额 向中央银行借款净增加额 向其他金融机构拆入资金净增加额 收到原保险合同保费取得的现金 保户储金净增加额 收到再保业务现金净额 处置交易性金融资产净增加额 收取利息和手续费净增加额 处置可供出售金融资产净增加额 拆入资金净增加额 回购业务资金净增加额 收到其他与经营活动有关的现金 经营活动现金流入小计 购买商品、接受劳务支付的现金 支付给职工以及为职工支付的现金 支付的各项税费 客户贷款及垫款净增加额 存放央行和同业款项净增加额 支付原保险合同赔付款项的现金 支付手续费的现金 支付保单红利的现金 支付其他与经营活动有关的现金 经营活动现金流出小计 经营活动产生的现金流量净额 收回投资收到的现金 取得投资收益收到的现金 处置固定资产、无形资产和其他长期资产收回的现金净额 处置子公司及其他营业单位收到的现金净额 收到其他与投资活动有关的现金 投资活动现金流入小计 购建固定资产、无形资产和其他长期资产支付的现金 投资支付的现金 取得子公司及其他营业单位支付的现金净额 支付其他与投资活动有关的现金 质押贷款净增加额 投资活动现金流出小计 投资活动产生的现金流量净额 吸收投资收到的现金 其中:子公司吸收少数股东投资收到的现金 取得借款收到的现金 发行债券收到的现金 收到其他与筹资活动有关的现金 筹资活动现金流入小计 偿还债务支付的现金 分配股利、利润或偿付利息支付的现金 其中:子公司支付给少数股东的股利、利润 支付其他与筹资活动有关的现金 筹资活动现金流出小计 筹资活动产生的现金流量净额 汇率变动对现金的影响 现金及现金等价物净增加额 期初现金及现金等价物余额 期末现金及现金等价物余额
B29: 企业利润表查询 | C29: 企业名称、统一信用代码、工商注册号、组织机构代码（4选1） | D29: 数据日期 408001000：合并报表 ; 408006000：母公司报表 营业总收入 营业收入 利息收入 利息净收入 已赚保费 手续费及佣金收入 手续费及佣金净收入 其他经营净收益 加:其他业务净收益 保费业务收入 减:分出保费 提取未到期责任准备金 其中:分保费收入 代理买卖证券业务净收入 证券承销业务净收入 受托客户资产管理业务净收入 其他业务收入 加:公允价值变动净收益 加:投资净收益 其中:对联营企业和合营企业的投资收益 加:汇兑净收益 营业总成本 减:营业成本 减:利息支出 减:手续费及佣金支出 减:营业税金及附加 减:销售费用 减:管理费用 减:财务费用 减:资产减值损失 退保金 赔付总支出 提取保险责任准备金 保户红利支出 分保费用 营业支出 减:摊回赔付支出 减:摊回保险责任准备金 减:摊回分保费用 其他业务成本 营业利润 加:营业外收入 减:营业外支出 其中:减:非流动资产处置净损失 利润总额 所得税 未确认投资损失 净利润(含少数股东损益) 净利润(不含少数股东损益) 少数股东损益 其他综合收益 综合收益总额 综合收益总额(母公司) 综合收益总额(少数股东) 其他收益
B30: 企业资产负债表查询 | C30: 企业名称、统一信用代码、工商注册号、组织机构代码（4选1） | D30: 数据日期 408001000：合并报表 ; 408006000：母公司报表 货币资金 交易性金融资产 应收票据 应收账款 其他应收款 预付款项 应收股利 应收利息 存货 消耗性生物资产 待摊费用 一年内到期的非流动资产 结算备付金 拆出资金 应收保费 应收分保账款 应收分保合同准备金 买入返售金融资产 其他流动资产 流动资产合计 可供出售金融资产 持有至到期投资 长期股权投资 投资性房地产 定期存款 其他资产 长期应收款 固定资产 在建工程 工程物资 固定资产清理 生产性生物资产 油气资产 无形资产 开发支出 商誉 长期待摊费用 递延所得税资产 发放贷款及垫款 其他非流动资产 非流动资产合计 现金及存放中央银行款项 存放同业和其它金融机构款项 贵金属 衍生金融资产 代理业务资产 应收代位追偿款 应收分保未到期责任准备金 应收分保未决赔款准备金 应收分保寿险责任准备金 应收分保长期健康险责任准备金 存出保证金 保户质押贷款 存出资本保证金 独立账户资产 客户资金存款 客户备付金 其中:交易席位费 应收款项类投资 资产总计 短期借款 向中央银行借款 吸收存款及同业存放 拆入资金 交易性金融负债 应付票据 应付账款 预收款项 卖出回购金融资产款 应付手续费及佣金 应付职工薪酬 应交税费 应付利息 应付股利 其他应付款 预提费用 递延收益 应付短期债券 应付分保账款 保险合同准备金 代理买卖证券款 代理承销证券款 一年内到期的非流动负债 其他流动负债 流动负债合计 长期借款 应付债券 长期应付款 专项应付款 预计负债 递延所得税负债 递延收益-非流动负债 其他非流动负债 非流动负债合计 同业和其它金融机构存放款项 衍生金融负债 吸收存款 代理业务负债 其他负债 预收保费 存入保证金 保户储金及投资款 未到期责任准备金 未决赔款准备金 寿险责任准备金 长期健康险责任准备金 独立账户负债 其中:质押借款 应付赔付款 应付保单红利 负债合计 股本 资本公积金 专项储备 盈余公积金 未分配利润 减:库存股 一般风险准备 外币报表折算差额 未确认的投资损失 少数股东权益 股东权益合计(不含少数股东权益) 股东权益合计(含少数股东权益) 负债及股东权益总计
B31: 企业主要指标(财务报表)查询 | C31: 企业名称、统一信用代码、工商注册号、组织机构代码（4选1） | D31: 数据日期 每股收益-基本 (元) 每股收益-稀释 (元) 每股收益-扣除/基本 (元) 每股净资产 (元) 每股经营活动产生的现金流量净额 每股资本公积 (元) 每股未分配利润 (元) 每股收益-基本 (元)-中位数 每股收益-稀释 (元)-中位数 每股收益-扣除/基本 (元)-中位数 每股净资产 (元)-中位数 每股经营活动产生的现金流量净额-中位数 每股资本公积 (元)-中位数 每股未分配利润 (元)-中位数 营业总收入同比增长率 营业收入同比增长率 同比增长率-利润总额 营业总收入同比增长率中位数 营业收入同比增长率中位数 同比增长率-利润总额中位数 净资产收益率(摊薄) 净资产收益率(加权) 净资产收益率(年化) 总资产报酬率 总资产报酬率(年化) 销售净利率 销售毛利率 营业利润/营业总收入 净资产收益率(摊薄)-中位数 净资产收益率(加权)-中位数 净资产收益率(年化)-中位数 总资产报酬率-中位数 总资产报酬率(年化)-中位数 销售净利率-中位数 销售毛利率-中位数 营业利润/营业总收入-中位数 销售收到现金流/营业收入 经营现金流/营业收入 销售收到现金流/营业收入-中位数 经营现金流/营业收入-中位数 应收账款周转天数 存货周转天数 总资产周转率 应收账款周转天数-中位数 存货周转天数-中位数 总资产周转率-中位数 流动比率 速动比率 利息保障倍数 流动比率-中位数 速动比率-中位数 利息保障倍数-中位数 流动资产/资产合计 非流动资产/资产合计 流动负债/负债合计 非流动负债/负债合计 资产负债率 流动资产/资产合计-中位数 非流动资产/资产合计-中位数 流动负债/负债合计-中位数 非流动负债/负债合计-中位数 资产负债率-中位数
B32: 企业财税分析 | C32: 企业名称、统一社会信用代码 | D32: 企业所得税基础信息
D33: 企业所得税年度申报表
D34: 企业所得税工资薪酬
D35: 企业所得税期间费用明细表
D36: 企业所得税资产折旧
D37: 研发费用明细表（部分行业）
D38: 高新企业明细表（部分行业）
D39: 一般企业收入明细表
D40: 未按权责发生制确认收入纳税调整明细表
...

Sheet 企业用电
A1: 企业用电
A2: 数据项 | B2: API名称 | C2: 输入参数 | D2: 具体内容/输出参数
A3: 用电数据 | B3: 企业用电数据标签 | C3: 企业信用代码、企业名称、授权文件全名（包含后缀）、授权时间） | D3: 开户距今天数
D4: 有效开户数
D5: 合同约定的本用户的容量
D6: 正在运行的合同容量
D7: 是否存在销户
D8: 用电时长是否大于12个月
D9: 用电时长是否大于24个月
D10: 注册资金（万元人民币）
D11: 省份代码
D12: 行业分类
D13: 企业当前状态代码
D14: 高耗能行业划分（碳化硅、钢铁、炭素、铁合金等）
D15: 客户用电类别（普通工业、大工业用电、商业用电、非工业等）
... D92: 近24个月申请修改的运行容量(减容)

Sheet 知识产权
A1: 知识产权
A2: 数据项 | B2: API名称 | C2: 输入参数 | D2: 具体内容/输出参数
B3: 企业商标信息查询 | C3: 企业名称、统一信用代码、工商注册号、组织机构代码（4选1） | D3: 商标名称
D4: 商标注册号
D5: 商标类别
D6: 商标进展
D7: 商标状态
D8: 申请人
D9: 申请日
D10: 初审公告日
D11: 注册公告日
D12: 专用权期限
D13: 专利代理机构
D14: 商标公告
D15: 商品/服务项目
... D21: 最新流程状态
B22: 企业域名信息查询 | C22: 企业名称、统一信用代码、工商注册号、组织机构代码（4选1） | D22: 企业id
D23: 企业名称
D24: 网站首页网址
D25: 网站备案许可证号
D26: 网站域名
D27: 网站名称
D28: 登记批准时间
B29: 企业著作权 | C29: 企业名称、统一信用代码、工商注册号、组织机构代码（4选1） | D29: 企业名称
D30: 类型
D31: 作品类别
D32: 登记号
D33: 分类号
D34: 作品名称
D35: 作品简称
D36: 版本号
D37: 创作完成日期
D38: 登记批准日期
D39: 首次发表日
D40: 是否有效(有效、无效)
B41: 企业专利 | C41: 企业名称、统一信用代码、工商注册号、组织机构代码（4选1） | D41: 专利权人
D42: 专利类型
D43: 发明人
D44: 地址
D45: 分类号
...

Sheet 婚姻核验
A1: 婚姻核验
A2: 数据项 | B2: API名称 | C2: 输入参数 | D2: 具体内容/输出参数
B3: 婚姻核验 | C3: 授权码、姓名、身份证号 | D3: 结果： 0-查询成功无数据（计费） 1-查询成功有数据（计费）
D4: 认证结果描述
D5: 查询结果 0：结婚、1：离婚、2：未匹配（未婚）、-1：数据源查询异常、-2：核查中
B6: 婚姻双查 | C6: 授权码、 男方姓名、 男方身份证号码、 女方姓名、 女方身份证号码、 | D6: 查询结果状态： 1：查询成功，有数据（计费） 0：查询成功，无数据（计费）
D7: 认证结果描述
D8: 查询结果0：结婚、1：离婚、2：未匹配

Sheet OCR识别
A1: OCR识别
A2: 数据项 | B2: API名称 | C2: 输入参数 | D2: 具体内容/输出参数
B3: 开户许可证OCR | C3: 识别证件 | D3: 依托前沿深度学习，利用光学字符识别（OCR）技术。通过采集开户许可证的扫描图片，对开户许可证的有效信息进行智能检测、定位、识别。
B4: 多类型证件OCR自动识别 | C4: 识别证件 | D4: 多种类型证件OCR自动识别功能，输入证照照片，自动识别出证件类型，并相应的识别出证件各个字段的信息。 目前支持身份证、护照、港澳通行证。
B5: 车牌号OCR识别 | C5: 车牌号图片 | D5: 依托前沿深度学习，利用光学字符识别（OCR）技术。通过采集自然场景下车牌号的扫描图片，可自动捕捉车牌号的边缘、校正透视变形图像，支持任意方向、正反图像自动识别。对车牌号的有效信息行智能检测、定位、识别，准确率可达99%以上。
B6: 通用文字识别 | C6: 图片 | D6: 依托前沿深度学习，利用光学字符识别（OCR）技术。通过采集自然场景下的扫描图片，可自动捕捉证件的边缘、校正透视变形图像，支持任意方向、正反图像自动识别。对卡片上的有效信息进行智能检测、定位、识别，准确率可达99%以上。
B7: 身份证OCR返回头像信息 | D7: 依托前沿深度学习，利用光学字符识别（OCR）技术。通过采集自然场景下身份证正反面的扫描图片，可自动捕捉身份证的边缘、校正透视变形图像，支持任意方向、正反图像自动识别。对身份证上中的有效信息行智能检测、定位、识别，返回身份证照片图片和身份证号等信息，准确率可达99%以上。
B8: 营业执照OCR识别 | C8: 需要识别的证件图 | D8: 依托前沿深度学习，利用光学字符识别（OCR）技术。通过采集自然场景下营业执照的扫描图片，对营业执照中的有效信息进行智能检测、定位、识别，准确率高。
B9: 通用发票OCR识别 | C9: 需要识别的图片 | D9: 依托前沿深度学习，利用光学字符识别（OCR）技术。通过采集自然场景下发票的扫描图片，对发票中的有效信息进行智能检测、定位、识别，准确率高。
B10: 电子承兑汇票OCR识别 | C10: 电子承兑汇票图片 | D10: 依托前沿深度学习，利用光学字符识别（OCR）技术。通过采集自然场景下电子承兑汇票的扫描图片，可自动捕捉电子承兑汇票的边缘、校正透视变形图像，支持任意方向、正反图像自动识别。对电子承兑汇票的有效信息行智能检测、定位、识别，准确率可达99%以上。
B11: 发票OCR识别 | C11: 增值税发票图片 | D11: 依托前沿深度学习，利用光学字符识别（OCR）技术。通过采集自然场景下发票的扫描图片，可自动捕捉发票的边缘、校正透视变形图像，支持任意方向、正反图像自动识别。对电子发票的有效信息行智能检测、定位、识别，准确率可达99%以上。
B12: 身份证OCR识别 | C12: 身份证照片图片 | D12: 依托前沿深度学习，利用光学字符识别（OCR）技术。通过采集自然场景下的扫描图片，可自动捕捉证件的边缘、校正透视变形图像，支持任意方向、正反图像自动识别。对卡片上的有效信息进行智能检测、定位、识别，准确率可达99%以上。
B13: 行驶证OCR识别 | C13: 行驶证图片 | D13: 依托前沿深度学习，利用光学字符识别（OCR）技术。通过采集自然场景下行驶证的扫描图片，可自动捕捉行驶证的边缘、校正透视变形图像，支持任意方向、正反图像自动识别。对行驶证的有效信息行智能检测、定位、识别，准确率可达99%以上。
B14: 护照OCR识别 | C14: 护照图片 | D14: 依托前沿深度学习，利用光学字符识别（OCR）技术。通过采集自然场景下护照的扫描图片，可自动捕捉护照的边缘、校正透视变形图像，支持任意方向、正反图像自动识别。对护照的有效信息行智能检测、定位、识别，准确率可达99%以上。
B15: 港澳居民来往内地通行证OCR识别 | C15: 图片的Base64加密字符串 | D15: 依托前沿深度学习，利用光学字符识别（OCR）技术。通过采集自然场景下港澳居民来往内地通行证OCR识别的扫描图片，可自动捕捉通行证的边缘、校正透视变形图像，支持任意方向、正反图像自动识别。对通行证的有效信息行智能检测、定位、识别，准确率可达99%以上。

Sheet 社保综合产品
A1: 社保综合产品
A2: 数据项 | B2: API名称 | C2: 输入参数 | D2: 具体内容/输出参数
B3: 企业及企业主能力评估 | C3: 身份证号（加密） 姓名 企业名称 统一社会信用代码 | D3: 对企业主还款能力、 还款稳定性进行评估， 对企业规模进行划型， 和违约风险评估及企业稳定性进行评估
B13: 企业主综合信息核验 | C13: 身份证号（加密） 姓名 企业名称 统一社会信用代码 核验标识 生存状态 行政区划代码 缴费状态 城镇累计缴费月数（年限） 连续缴费月数 城镇个人缴费基数（档次） 城乡累计缴费月数（年限） 城乡个人缴费基数（档次） 企业主养老待遇领取状态 企业主当前单位工作时长 | D13: 对企业主所在单位、参保注销状态、累计缴费月数/年限、连续缴费月数、缴费基数/档次、缴费城市、缴费状态、养老待遇领取状态、工作单位市场、缴费城市稳定性进行核验
B23: 企业综合信息核验 | C23: 企业名称 统一社会信用代码 | D23: 对企业参保市场、员工人数、员工变动情况、缴费状态、缴费次数、缴费基数、平均实缴金额、员工平均缴费基数、缴费中位数、年度未单位人数进行核验

Sheet 电商数据
A1: 电商数据
A2: 数据项 | B2: API名称 | C2: 输入参数 | D2: 具体内容/输出参数
A3: 电商数据 | B3: 电商白名单标准筛选 | C3: 按地区筛选 | D3: 企业名称、统一社会信用代码、注册地址，联系电话。
B4: 电商白名单定制化筛选 | C4: 按地区、平台、销售额、行业筛选 | D4: 企业名称、统一社会信用代码、注册地址，联系电话。
B5: 电商数据查询 | C5: 公司名称、统一社会信用代码、授权协议编号 | D5: 企业名称、统一社会信用代码、零售额、零售量、店铺数量、经销商数量、品牌数量、商品数量、所在平台、店铺名称、店铺零售额、注册地址、法人、行业、注册资本、经营范围

Sheet 烟草
A1: 烟草
A2: 数据项 | B2: API名称 | C2: 输入参数 | D2: 具体内容/输出参数
A3: 烟草商户经营标签查询 | B3: 认证结果查询 | C3: 认证地址交易流水号、查询原因、业务描述、信息主体授权码、信息主体授权时间 | D3: 基本信息
D4: 订单信息
D5: 额度分析
D6: 次数分析
D7: 协议

Sheet 不动产
A1: 不动产
A2: 产品大类 | B2: 产品名称 | C2: 入参 | D2: 出参
A3: 个人资产 | B3: 不动产 | C3: 姓名、身份证号、授权协议编码 | D3: 不动产权证号
D4: 房屋用途
D5: 房屋性质
D6: 不动产坐落
D7: 面积
D8: 共有情况
D9: 是否查封
D10: 是否抵押

Sheet 反欺诈
A1: 贸易反欺诈
A2: 大分类 | B2: 一级标题 | C2: 二级标题 | D2: 子字段
A3: 反欺诈维度 | B3: 支出真实性考量 | C3: 费用真实性识别 | D3: 咨询费
D4: 咨询顾问费占比销管费用
D5: 费用真实性概述
D6: 费用真实性预警
D7: 费用真实性识别
C8: 货物实际流转识别 | D8: 货物流转费用
D9: 货物流转费用与总收入的占比
D10: 货物流转费用识别结论
D11: 货物流转费用概述
D12: 货物流转费用预警
D13: 成品油支出
D14: 物流运输费用
D15: 仓储费用
B16: 收入真实性考量 | C16: 资金流转速率识别 | D16: 资金流转速率结论
D17: 资金流转速率概述
D18: 资金流转速率
D19: 资金流转速率预警
C20: 闭环交易识别 | D20: 来源于闭环交易的收入
D21: 闭环交易的收入与总收入占比
D22: 闭环交易识别结论
D23: 闭环交易识别概述
D24: 闭环交易企业数量
C25: 人均产值合理性识别 | D25: 职工人数
D26: 人均产值合理性结论
D27: 人均产值合理性概述
D28: 人均产值
D29: 人均产值合理性预警
C30: 关联交易识别 | D30: 关联交易企业数量
D31: 来源于关联交易的收入
D32: 关联交易的收入与总收入占比
D33: 关联交易识别结论
D34: 关联交易识别概述
B35: 利润来源考量 | C35: 利润与主营关系识别 | D35: 金融活动收益
D36: 主营业务收益
D37: 利润来源考量结论
D38: 利润来源考量概述
D39: 利润来源考量预警

Sheet 其他
A1: 其他
A2: 数据项 | B2: API名称 | C2: 输入参数 | D2: 具体内容/输出参数
A3: AI智能 | B3: 身份证三要素核验 | C3: 持证人照片、身份证照片 | D3: 姓名，身份证号，人脸照片核验
A4: 交通运输 | B4: 车辆完整信息（车架号） | C4: 车架号 | D4: 基于500万+重载货运车辆的大数据基础上，车架号列表查询
B5: 企业道路运输经营许可证验证V3 | C5: 经营许可证号，企业名称 | D5: 基于重载货运车辆的大数据基础上，可经过经营许可证号和企业名称，对道路运输证信息进行验证
B6: 道路运输许可证核验 | C6: 车牌号，车牌颜色代码 | D6: 基于500万+重载货运车辆的大数据基础上，车牌号、车牌颜色查询道路运输证号码及有效期等信息。
A7: 营销数据 | B7: 画像标签 | D7: 包括：人口属性、应用行为、位置行为、行业标签、广告行为、设备信息等全量标签。
B8: 金融特征 | D8: 基于金融APP使用偏好特征、营销特征、地理位置特征、设备信息特征、交叉特征类、embedding特征类、人口属性类的特征标签
B9: 小微分 | D9: 识别小微企业主，分数越高代表小微企业主的可能性越高
B10: 申请分 | D10: 识别金融信贷申请意向用户，分数越高代表申请借贷意向越高
B11: 授信分 | D11: 识别金融信贷用户资质，分数越高代表质量越高，完成授信的可能越大
B12: 反欺诈标签 | D12: 基于设备中网贷、传销、涉诈、涉赌等app安装及活跃情况识别；
B13: 投诉标签 | D13: 基于设备中投诉类app安装及活跃情况识别
